<?xml version="1.0" ?>
<robot name="uni_base" xmlns:xacro="http://ros.org/wiki/xacro">
  <xacro:include filename="$(find uni_description)/urdf/uni_base.gazebo.xacro"/>

  <link name="base_footprint"/>

  <joint name="base_footprint_joint" type="fixed">
    <parent link="base_footprint"/>
    <child link="base_link" />
    <origin xyz="0 0 0.07" rpy="0 0 0"/>
  </joint>

  <link name="base_link">
    <visual>
      <origin xyz="0 0 -0.01" rpy="0 0 1.57"/>
      <geometry>
        <mesh filename="package://uni_description/meshes/B1_base_mesh.stl" scale="0.007 0.007 0.007"/>
      </geometry>
    </visual>
    <collision>
      <origin xyz="0 0 0.15" rpy="0 0 0"/>
      <geometry>
        <cylinder length="0.3" radius="0.2"/>
      </geometry>
    </collision>

    <inertial>
      <origin xyz="0 0 0.14" rpy="0 0 0"/>
      <mass value="36.22"/>
      <inertia ixx="1.760901" ixy="2.081e-3" ixz="1.6376223e-01"
               iyy="2.069692" iyz="3.146e-05"
               izz="1.08381489" />
    </inertial>
  </link>

  <joint name="wheel_left_joint" type="continuous">
    <parent link="base_link"/>
    <child link="wheel_left_link"/>
    <origin xyz="0.0 0.175 0.025" rpy="-1.57 0 0"/>
    <axis xyz="0 0 1"/>
  </joint>

  <link name="wheel_left_link">
    <visual>
      <origin xyz="0 0 -0.025" rpy="0 1.57 0"/>
      <geometry>
        <mesh filename="package://uni_description/meshes/wheel_L.stl"/>
      </geometry>
    </visual>

    <collision>
      <origin xyz="0 0 0" rpy="0 0 0"/>
      <geometry>
        <cylinder length="0.025" radius="0.065"/>
      </geometry>
    </collision>

    <inertial>
      <origin xyz="0 0 0" />
      <mass value="1.8985" />
      <inertia ixx="2.998261e-03" ixy="2.07094e-19" ixz="1.86545e-19"
               iyy="2.998261e-03" iyz="-9.08019e-20"
               izz="5.556445e-03" />
    </inertial>
  </link>

  <link name="wheel_right_link">
    <visual>
      <origin xyz="0 0 0.025" rpy="0 1.57 0"/>
      <geometry>
        <mesh filename="package://uni_description/meshes/wheel_R.stl"/>
      </geometry>
    </visual>

    <collision>
      <origin xyz="0 0 0" rpy="0 0 0"/>
      <geometry>
        <cylinder length="0.025" radius="0.065"/>
      </geometry>
    </collision>

    <inertial>
      <origin xyz="0 0 0" />
      <mass value="1.8985" />
      <inertia ixx="2.998261e-03" ixy="2.07094e-19" ixz="1.86545e-19"
               iyy="2.998261e-03" iyz="-9.08019e-20"
               izz="5.556445e-03" />
    </inertial>
  </link>

  <joint name="wheel_right_joint" type="continuous">
    <parent link="base_link"/>
    <child link="wheel_right_link"/>
    <origin xyz="0.0 -0.175 0.025" rpy="-1.57 0 0"/>
    <axis xyz="0 0 1"/>
  </joint>


  <link name="caster_front_right_link">
    <collision>
      <origin xyz="0 0.001 0" rpy="0 0 0"/>
      <geometry>
        <sphere radius="0.0375"/>
      </geometry>
    </collision>

    <visual>
      <origin xyz="0 0.001 0" rpy="0 0 0"/>
      <geometry>
        <sphere radius="0.0375"/>
      </geometry>
    </visual>

    <inertial>
      <origin xyz="0 0 0" />
      <mass value="0.005" />
      <inertia ixx="0.001" ixy="0.0" ixz="0.0"
               iyy="0.001" iyz="0.0"
               izz="0.001" />
    </inertial>
  </link>

  <joint name="caster_front_right_joint" type="fixed">
    <parent link="base_link"/>
    <child link="caster_front_right_link"/>
    <origin xyz="0.158 -0.105 -0.0005" rpy="-1.57 0 0"/>
  </joint>

  <link name="caster_front_left_link">
    <collision>
      <origin xyz="0 0.001 0" rpy="0 0 0"/>
      <geometry>
        <sphere radius="0.0375"/>
      </geometry>
    </collision>

    <visual>
      <origin xyz="0 0.001 0" rpy="0 0 0"/>
      <geometry>
        <sphere radius="0.0375"/>
      </geometry>
    </visual>

    <inertial>
      <origin xyz="0 0 0" />
      <mass value="0.005" />
      <inertia ixx="0.001" ixy="0.0" ixz="0.0"
               iyy="0.001" iyz="0.0"
               izz="0.001" />
    </inertial>
  </link>

  <joint name="caster_front_left_joint" type="fixed">
    <parent link="base_link"/>
    <child link="caster_front_left_link"/>
    <origin xyz="0.158 0.105 -0.0005" rpy="-1.57 0 0"/>
  </joint>

  <link name="caster_back_right_link">
    <collision>
      <origin xyz="0 0.001 0" rpy="0 0 0"/>
      <geometry>
        <sphere radius="0.0375"/>
      </geometry>
    </collision>

    <visual>
      <origin xyz="0 0.001 0" rpy="0 0 0"/>
      <geometry>
        <sphere radius="0.0375"/>
      </geometry>
    </visual>

    <inertial>
      <origin xyz="0 0 0" />
      <mass value="0.005" />
      <inertia ixx="0.001" ixy="0.0" ixz="0.0"
               iyy="0.001" iyz="0.0"
               izz="0.001" />
    </inertial>
  </link>

  <joint name="caster_back_right_joint" type="fixed">
    <parent link="base_link"/>
    <child link="caster_back_right_link"/>
    <origin xyz="-0.158 -0.105 -0.0005" rpy="-1.57 0 0"/>
  </joint>

  <link name="caster_back_left_link">
    <collision>
      <origin xyz="0 0.001 0" rpy="0 0 0"/>
      <geometry>
        <sphere radius="0.0375"/>
      </geometry>
    </collision>

    <visual>
      <origin xyz="0 0.001 0" rpy="0 0 0"/>
      <geometry>
        <sphere radius="0.0375"/>
      </geometry>
    </visual>

    <inertial>
      <origin xyz="0 0 0" />
      <mass value="0.005" />
      <inertia ixx="0.001" ixy="0.0" ixz="0.0"
               iyy="0.001" iyz="0.0"
               izz="0.001" />
    </inertial>
  </link>

  <joint name="caster_back_left_joint" type="fixed">
    <parent link="base_link"/>
    <child link="caster_back_left_link"/>
    <origin xyz="-0.158 0.105 -0.0005" rpy="-1.57 0 0"/>
  </joint>

  <link name="imu_link"/>
  <joint name="imu_joint" type="fixed">
    <parent link="base_link"/>
    <child link="imu_link"/>
    <origin xyz="0.0 0 0.068" rpy="0 0 0"/>
  </joint>

  <link name="front_laser">
    <visual>
      <origin xyz="0.01 0 -0.04" rpy="0 -1.57 -1.57"/>
      <geometry>
        <mesh filename="package://uni_description/meshes/TiM571.stl" scale="0.001 0.001 0.001"/>
      </geometry>
    </visual>

    <collision>
      <origin xyz="0.015 0 -0.0065" rpy="0 -1.57 -1.57"/>
      <geometry>
        <cylinder length="0.0315" radius="0.055"/>
      </geometry>
    </collision>

    <inertial>
      <mass value="0.001" />
      <origin xyz="0 0 0" />
      <inertia ixx="0.001" ixy="0.0" ixz="0.0"
               iyy="0.001" iyz="0.0"
               izz="0.001" />
    </inertial>
  </link>

  <joint name="scan_joint" type="fixed">
    <origin xyz="0.238 0 0.152" rpy="0 0 0"/>
    <parent link="base_link"/>
    <child link="front_laser"/>
  </joint>

  <link name="front_astra_camera">
    <visual>
      <origin xyz="-0.004 0.071 -0.129" rpy="0 0 1.57"/>
      <geometry>
        <mesh filename="package://uni_description/meshes/gazebo_astra.stl" scale="0.001 0.001 0.001" />
      </geometry>
    </visual>

    <collision>
      <origin xyz="0.005 0.011 0.013" rpy="0 0 0"/>
      <geometry>
        <box size="0.015 0.030 0.027"/>
      </geometry>
    </collision>
  </link>

  <joint name="camera_joint" type="fixed">
    <origin xyz="0.246 -0.02 0.212" rpy="0 0 0"/>
    <parent link="base_link"/>
    <child link="front_astra_camera"/>
  </joint>

  <joint name="camera_rgb_joint" type="fixed">
    <origin xyz="0.003 0.011 0.009" rpy="0 0 0"/>
    <parent link="front_astra_camera"/>
    <child link="camera_rgb_frame"/>
  </joint>

  <link name="camera_rgb_frame"/>

  <joint name="camera_rgb_optical_joint" type="fixed">
    <origin xyz="0 0 0" rpy="-1.57 0 -1.57"/>
    <parent link="camera_rgb_frame"/>
    <child link="camera_rgb_optical_frame"/>
  </joint>

  <link name="camera_rgb_optical_frame"/>

  <joint name="camera_depth_joint" type="fixed">
    <origin xyz="0 0.025 0" rpy="0 0 0"/>
    <parent link="front_astra_camera"/>
    <child link="camera_depth_frame"/>
  </joint>

  <link name="camera_depth_frame"/>

  <!-- Image an CameraInfo message headers shouldga reference the camera_link_optical frame-->

  <joint name="camera_depth_optical_joint" type="fixed">
    <origin xyz="0 0 0" rpy="-1.57 0 -1.57"/>
    <parent link="camera_depth_frame"/>
    <child link="camera_depth_optical_frame"/>
  </joint>

  <link name="camera_depth_optical_frame"/>
  
  <!-- gtec base object(sensor,camera) -->
  <!-- ocam_1 카메라 추가 -->
  <link name="ocam_1_link">
    <visual>
      <origin xyz="0 0 0" rpy="0 0 0"/>
      <geometry>
        <mesh filename="package://uni_description/meshes/ocam_1.stl" scale="0.001 0.001 0.001"/>
      </geometry>
    </visual>
  </link>
  <joint name="ocam_1_joint" type="fixed">
    <parent link="base_link"/>
    <child link="ocam_1_link"/>
    <origin xyz="0.072 0.197 0.434" rpy="0 0 2.3284"/>
  </joint>
  
  <link name="ocam_2_link">
    <visual>
      <origin xyz="0 0 0" rpy="0 0 0"/>
      <geometry>
        <mesh filename="package://uni_description/meshes/ocam_2.stl" scale="0.001 0.001 0.001"/>
      </geometry>
    </visual>
  </link>
  <joint name="ocam_2_joint" type="fixed">
    <parent link="base_link"/>
    <child link="ocam_2_link"/>
    <origin xyz="0.197 -0.07 0.434" rpy="0 0 0.7584"/>
  </joint>

  <link name="ocam_3_link">
    <visual>
      <origin xyz="0 0 0" rpy="0 0 0"/>
      <geometry>
        <mesh filename="package://uni_description/meshes/ocam_3.stl" scale="0.001 0.001 0.001"/>
      </geometry>
    </visual>
  </link>
  <joint name="ocam_3_joint" type="fixed">
    <parent link="base_link"/>
    <child link="ocam_3_link"/>
    <origin xyz="-0.070 -0.195 0.434" rpy="0 0 -0.7584"/>
  </joint>

  <link name="ocam_4_link">
    <visual>
      <origin xyz="0 0 0" rpy="0 0 0"/>
      <geometry>
        <mesh filename="package://uni_description/meshes/ocam_4.stl" scale="0.001 0.001 0.001"/>
      </geometry>
    </visual>
  </link>
  <joint name="ocam_4_joint" type="fixed">
    <parent link="base_link"/>
    <child link="ocam_4_link"/>
    <origin xyz="0.088 -0.215 0.434" rpy="0 0 -2.3284"/>
  </joint>

  <link name="ocam_5_link">
    <visual>
      <origin xyz="0 0 0" rpy="0 0 0"/>
      <geometry>
        <mesh filename="package://uni_description/meshes/ocam_5.stl" scale="0.001 0.001 0.001"/>
      </geometry>
    </visual>
  </link>
  <joint name="ocam_5_joint" type="fixed">
    <parent link="base_link"/>
    <child link="ocam_5_link"/>
    <origin xyz="-0.088 0.213 0.434" rpy="0 0 0.7584"/>
  </joint>

  <link name="ocam_6_link">
    <visual>
      <origin xyz="0 0 0" rpy="0 0 0"/>
      <geometry>
        <mesh filename="package://uni_description/meshes/ocam_6.stl" scale="0.001 0.001 0.001"/>
      </geometry>
    </visual>
  </link>
  <joint name="ocam_6_joint" type="fixed">
    <parent link="base_link"/>
    <child link="ocam_6_link"/>
    <origin xyz="0.215 0.09 0.434" rpy="0 0 -0.7584"/>
  </joint>
  
    <!-- astra2_1 상단부 오른쪽 카메라 형상 추가 -->
  <link name="astra2_1_link">
    <visual>
      <origin xyz="0 0 0" rpy="0 0 0"/>
      <geometry>
        <mesh filename="package://uni_description/meshes/astra2_1.stl" scale="0.001 0.001 0.001"/>
      </geometry>
    </visual>
  </link>
  <joint name="astra2_1_joint" type="fixed">
    <parent link="base_link"/>
    <child link="astra2_1_link"/>
    <origin xyz="0.15 -0.16 0.83" rpy="0 0 -0.7584"/>
  </joint>

    <!-- astra2_2 상단부 왼쪽 카메라 형상 추가 -->
  <link name="astra2_2_link">
    <visual>
      <origin xyz="0 0 0" rpy="0 0 0"/>
      <geometry>
        <mesh filename="package://uni_description/meshes/astra2_2.stl" scale="0.001 0.001 0.001"/>
      </geometry>
    </visual>
  </link>
  <joint name="astra2_2_joint" type="fixed">
    <parent link="base_link"/>
    <child link="astra2_2_link"/>
    <origin xyz="0.15 0.16 0.83" rpy="0 0 0.7584"/>
  </joint>
    <!-- astra2_3 상단부 가운데 카메라 형상 추가 -->
  <link name="astra2_3_link">
    <visual>
      <origin xyz="0 0 0" rpy="0 0 0"/>
      <geometry>
        <mesh filename="package://uni_description/meshes/astra2_3.stl" scale="0.001 0.001 0.001"/>
      </geometry>
    </visual>
  </link>
  <joint name="astra2_3_joint" type="fixed">
    <parent link="base_link"/>
    <child link="astra2_3_link"/>
    <origin xyz="0.2 0 0.833" rpy="0 0 0"/>
  </joint>

  <link name="astra_embedded_s_link">
    <visual>
      <origin xyz="0 0 0" rpy="0 0 0"/>
      <geometry>
        <mesh filename="package://uni_description/meshes/astra_embedded_s.stl" scale="0.001 0.001 0.001"/>
      </geometry>
    </visual>
  </link>
  <joint name="astra_embedded_s_joint" type="fixed">
    <parent link="base_link"/>
    <child link="astra_embedded_s_link"/>
    <origin xyz="0.25 0 0.338" rpy="0 0 0"/>
  </joint>
  
      <!-- mw-ahrs_v1_imu 자이로센서 형상 추가  -->
    <link name="mw_ahrs_v1_imu_link">
    <visual>
      <origin xyz="0 0 0" rpy="0 0 0"/>
      <geometry>
        <mesh filename="package://uni_description/meshes/mw_ahrs_v1_imu.stl" scale="0.007 0.007 0.007"/>
      </geometry>
    </visual>
  </link>
  <joint name="mw_ahrs_v1_imu_joint" type="fixed">
    <parent link="base_link"/>
    <child link="mw_ahrs_v1_imu_link"/>
    <origin xyz="0 0 -0.01" rpy="0 0 1.57"/>
  </joint>
  
</robot>

